Workbook

Sheet TAZMİNAT TAKİP
A1: İSİM | B1: TARİH | C1: PLAN | D1: İŞLEM | E1: AÇIKLAMA | F1: TUTAR
A2: İBRAHİM AKYOL | B2: 44209 | D2: TAHAKKUK | F2: 30800
A3: İBRAHİM AKYOL | B3: 44209 | D3: ÖDEME | F3: -5000
A4: İBRAHİM AKYOL | B4: 44245 | D4: ÖDEME | F4: -5000
A5: İBRAHİM AKYOL | B5: 44273 | D5: ÖDEME | F5: -10000
A6: İBRAHİM AKYOL | B6: 44343 | D6: ÖDEME | F6: -3500
A7: İBRAHİM AKYOL | B7: 44413 | D7: ÖDEME | F7: -4000
A8: İBRAHİM AKYOL | D8: ÖDEME
A9: ÇETİN ERGİN | B9: 44255 | D9: TAHAKKUK | F9: 4391
A10: ÇETİN ERGİN | D10: ÖDEME | F10: -4391
A11: ÖMER KÖROĞLU | B11: 44242 | D11: TAHAKKUK | F11: 10478.42
A12: ÖMER KÖROĞLU | B12: 44326 | D12: ÖDEME | F12: -5000
A13: ÖMER KÖROĞLU | D13: ÖDEME | F13: -5478.42
A14: FEZAİL ÇAPKIN | D14: TAHAKKUK | E14: Arabuluculuk | F14: 6500
A15: FEZAİL ÇAPKIN | B15: 44250 | D15: ÖDEME | F15: -3250
A16: FEZAİL ÇAPKIN | B16: 44278 | D16: ÖDEME | F16: -3250
A17: RÜSTEM ÜLFEN | B17: 44357 | D17: TAHAKKUK | F17: 4354.24
A18: RÜSTEM ÜLFEN | D18: ÖDEME | F18: -2000.24
A19: RÜSTEM ÜLFEN | D19: ÖDEME | F19: -2354
A20: BEKİR TAŞÇILAR | B20: 44335 | D20: TAHAKKUK | F20: 3000
A21: BEKİR TAŞÇILAR | D21: ÖDEME | F21: -1000
A22: BEKİR TAŞÇILAR | D22: ÖDEME | F22: -2000
A23: IŞIL UZAN | B23: 43979 | D23: TAHAKKUK | F23: 13720.35
A24: IŞIL UZAN | D24: ÖDEME | F24: -10020.35
A25: IŞIL UZAN | D25: ÖDEME | F25: -7000
A26: MELİK KAHRAMAN | B26: 44805 | D26: TAHAKKUK | F26: 9570
A27: MELİK KAHRAMAN | B27: 44805 | D27: ÖDEME | F27: -4570
F29: =SUBTOTAL(109,Tablo3[TUTAR]) -> 5000

Sheet AyrılanPersonelListesi
A1: PERSONEL | B1: MAAŞ TUTARI | C1: DURUM | D1: GÖREV | E1: GERÇEK MAAŞ | F1: SGK M. | G1: SGK FM. | H1: Eksik Gün-Kesinti | I1: yi | J1: Sütun1 | K1: Durum2 | L1: SSK FRM | M1: TC KİMLİK NO | N1: MÜŞT. NO | O1: EK | P1: İşe B. Tar.
A2: BEKİR TAŞÇILAR | B2: 547 | C2: EMEKLİ | D2: _ŞOFÖR | E2: 3600 | F2: 547 | G2: 0 | H2: 25 | I2: =SUMIF(bordro[Personel],personelListesiGuncel[[#This Row],[PERSONEL]],bordro[Yİ]) -> 0 | K2: Çıktı | L2: Y KUM | M2: 18274523170 | N2: 95532068 | O2: 1
A3: RÜSTEM ÜLFEM | B3: 3600 | C3: ÇALIŞAN | D3: _ELEMAN | E3: 3600 | F3: 3100 | G3: 500 | I3: =SUMIF(bordro[Personel],personelListesiGuncel[[#This Row],[PERSONEL]],bordro[Yİ]) -> 0 | K3: Çıktı | L3: Y KUM | M3: 39617231002 | N3: 95532072 | O3: 1
A4: NECDET ÇALIK | B4: 3353.97 | C4: ÇALIŞAN | D4: _BEKÇİ | E4: 3353.97 | F4: 3053.97 | G4: 300 | I4: =SUMIF(bordro[Personel],personelListesiGuncel[[#This Row],[PERSONEL]],bordro[Yİ]) -> 0 | K4: Çıktı | L4: HALİL Y | M4: 40340193420 | N4: 97253706 | O4: 1 | R4: 4000
A5: MESUT ÇAVDAR | B5: =personelListesiGuncel[[#This Row],[SGK M.]]+personelListesiGuncel[[#This Row],[yi]] -> 1670 | C5: EMEKLİ | D5: _ŞOFÖR | E5: 6000 | F5: 4253 | G5: 0 | H5: 1.000 kesiniti | I5: =SUMIF(bordro[Personel],personelListesiGuncel[[#This Row],[PERSONEL]],bordro[Yİ]) -> 0 | K5: Çalışan | L5: Y KUM | M5: 11707921468 | N5: 94987081 | O5: 1
A6: YILMAZ YILMAZ | B6: =personelListesiGuncel[[#This Row],[SGK M.]]+personelListesiGuncel[[#This Row],[yi]] -> 40000 | C6: EMEKLİ | D6: _ŞOFÖR | E6: 6000 | F6: 0 | G6: 0 | H6: 30 | I6: =SUMIF(bordro[Personel],personelListesiGuncel[[#This Row],[PERSONEL]],bordro[Yİ]) -> 0 | K6: Çalışan | L6: Y KUM | M6: 15394555838 | N6: 95580195 | O6: 1
A7: YAVUZ YILMAZ | B7: =personelListesiGuncel[[#This Row],[SGK M.]]+personelListesiGuncel[[#This Row],[yi]] -> 22104 | C7: ÇALIŞAN | D7: _KANTAR | E7: 6000 | F7: 4253.39 | G7: 477 | I7: =SUMIF(bordro[Personel],personelListesiGuncel[[#This Row],[PERSONEL]],bordro[Yİ]) -> 0 | K7: Çalışan | L7: HALİL Y | M7: 39043021192
A8: ŞİRİN GENCE | B8: =personelListesiGuncel[[#This Row],[SGK M.]]+personelListesiGuncel[[#This Row],[yi]] -> 1603 | C8: ÇALIŞAN | D8: _BEKÇİ | E8: 4730.4 | F8: 4253.4 | G8: 477 | H8: İcra 1/4 -1.000 | I8: =SUMIF(bordro[Personel],personelListesiGuncel[[#This Row],[PERSONEL]],bordro[Yİ]) -> 0 | K8: Çalışan | L8: HALİL Y | M8: 66385338732 | N8: 96717247 | O8: 1
A9: MELEKNUR YILMAZ | B9: =personelListesiGuncel[[#This Row],[SGK M.]]+personelListesiGuncel[[#This Row],[yi]] -> 2335 | C9: ÇALIŞAN | D9: _MUHASEBE | F9: 4250 | G9: 0 | H9: 0 | K9: =SUMIF(bordro[Personel],personelListesiGuncel[[#This Row],[PERSONEL]],bordro[Yİ]) -> 0 | L9: Çalışan | M9: HALİL Y | N9: 64996156028 | O9: 95539771 | P9: 1
A10: AJDA ÖZENER | B10: =personelListesiGuncel[[#This Row],[SGK M.]]+personelListesiGuncel[[#This Row],[yi]] -> 2000 | C10: ÇALIŞAN | D10: _AİLE | F10: 5500 | G10: 5500 | H10: 0 | K10: =SUMIF(bordro[Personel],personelListesiGuncel[[#This Row],[PERSONEL]],bordro[Yİ]) -> 0 | L10: Çalışan | M10: HALİL Y | N10: 22093575890 | O10: 96260905 | P10: 1
A11: AYŞEGÜL OZANER | B11: =personelListesiGuncel[[#This Row],[SGK M.]]+personelListesiGuncel[[#This Row],[yi]] -> 35000 | C11: ÇALIŞAN | D11: _AİLE | F11: 5500 | G11: 5500 | H11: 0 | K11: =SUMIF(bordro[Personel],personelListesiGuncel[[#This Row],[PERSONEL]],bordro[Yİ]) -> 0 | L11: Çalışan | M11: HALİL Y | N11: 30148302742 | O11: 97726066 | P11: 1
A12: ALFİA FERMAN | B12: =personelListesiGuncel[[#This Row],[SGK M.]]+personelListesiGuncel[[#This Row],[yi]] -> 33000 | C12: ÇALIŞAN | D12: _AİLE | F12: 5500 | G12: 5500 | H12: 0 | K12: =SUMIF(bordro[Personel],personelListesiGuncel[[#This Row],[PERSONEL]],bordro[Yİ]) -> 0 | L12: Çalışan | M12: HALİL Y | N12: 74524099696
A13: ORHAN UZUN | B13: =personelListesiGuncel[[#This Row],[SGK M.]]+personelListesiGuncel[[#This Row],[yi]] -> 0 | C13: ÇALIŞAN | D13: _OPERATÖR | E13: 7200 | F13: 5500 | G13: 550 | I13: =SUMIF(bordro[Personel],personelListesiGuncel[[#This Row],[PERSONEL]],bordro[Yİ]) -> 0 | K13: Çalışan | L13: HALİL Y | M13: 59233322526 | N13: 96712272 | O13: 1
A14: MELİK KAHRAMAN | B14: 997.61 | C14: EMEKLİ | D14: _ŞOFÖR | E14: 50 | F14: 8000 | G14: 997.61 | H14: 0 | I14: 25 | J14: 16 | K14: Çalışan | L14: HALİL Y | M14: 13345619462 | N14: 97522183 | O14: 1 | Q14: MELİK KAHRAMAN | R14: 997.61
A15: KERİM ŞİMŞEK | B15: 997.61 | C15: EMEKLİ | D15: _ŞOFÖR | E15: 50 | F15: 7500 | G15: 997.61 | H15: 0 | I15: 25 | J15: 0 | K15: Çalışan | L15: Y KUM | M15: 27172394690 | N15: 95702622 | O15: 1 | Q15: RAMAZAN TUNCER | R15: 5500.35
A16: BEKİR TAŞÇILAR | B16: =personelListesiGuncel[[#This Row],[SGK M.]]+personelListesiGuncel[[#This Row],[yi]] -> 15000 | C16: EMEKLİ | D16: _ŞOFÖR | E16: 80 | F16: 12500 | G16: 9144.81 | H16: 0 | J16: =SUMIF(bordro[Personel],personelListesiGuncel[[#This Row],[PERSONEL]],bordro[Yİ]) -> 0 | K16: Çıktı | L16: HALİL Y | M16: 18274523170 | N16: 95532068 | O16: 1 | Q16: ŞİNASİ VURAL POLAT | R16: 0 | S16: 0
A17: DENİZ DALKILINÇ | B17: =personelListesiGuncel[[#This Row],[SGK M.]]+personelListesiGuncel[[#This Row],[yi]] -> 1603 | C17: ÇALIŞAN | D17: _ŞOFÖR | E17: 80 | F17: 14500 | G17: 9460.77 | H17: 0 | J17: =SUMIF(bordro[Personel],personelListesiGuncel[[#This Row],[PERSONEL]],bordro[Yİ]) -> 0 | K17: Çıktı | L17: HALİL Y | M17: 38614007368 | N17: 97665848 | O17: 1 | Q17: DENİZ DALKILINÇ | R17: 4070.25 | S17: 14500
I18: =SUMIF(bordro[Personel],personelListesiGuncel[[#This Row],[PERSONEL]],bordro[Yİ]) -> 0
I19: =SUMIF(bordro[Personel],personelListesiGuncel[[#This Row],[PERSONEL]],bordro[Yİ]) -> 0
A20: TOPLAM | B20: =SUBTOTAL(109,personelListesiGuncel8[MAAŞ TUTARI]) -> 163811.19 | E20: =SUBTOTAL(109,personelListesiGuncel8[GERÇEK MAAŞ]) -> 40744.37 | F20: =SUBTOTAL(109,personelListesiGuncel8[SGK M.]) -> 88210.76 | G20: =SUBTOTAL(109,personelListesiGuncel8[SGK FM.]) -> 39404.8 | H20: =SUBTOTAL(109,personelListesiGuncel8[Eksik Gün-Kesinti]) -> 55 | I20: =SUBTOTAL(109,personelListesiGuncel8[yi]) -> 50

Sheet PersonelListesi
A1: PERSONEL | B1: MAAŞ TUTARI | C1: DURUM | D1: GÖREV | E1: FM Saat Ücr. | F1: GERÇEK MAAŞ | G1: SGK M. | H1: yi | I1: Durum2 | J1: SSK FRM | K1: TC KİMLİK NO
A2: ABDULLAH KARAHANCI | B2: =personelListesiGuncel[[#This Row],[SGK M.]]+personelListesiGuncel[[#This Row],[yi]] -> 40000 | C2: ÇALIŞAN | D2: _MUHASEBE | F2: 57500 | G2: 40000 | H2: =SUMIF(bordro[Personel],personelListesiGuncel[[#This Row],[PERSONEL]],bordro[Yİ]) -> 0 | I2: Çalışan | J2: HALİL Y | K2: 28699369338
A3: DURSUN DURMUŞ | B3: =personelListesiGuncel[[#This Row],[SGK M.]]+personelListesiGuncel[[#This Row],[yi]] -> 2670 | C3: EMEKLİ | D3: _D.ELEMAN | E3: 230 | F3: 75000 | G3: 2670 | H3: =SUMIF(bordro[Personel],personelListesiGuncel[[#This Row],[PERSONEL]],bordro[Yİ]) -> 0 | I3: Çalışan | J3: HALİL Y | K3: 17630785580
A4: RAMAZAN TUNCER | B4: =personelListesiGuncel[[#This Row],[SGK M.]]+personelListesiGuncel[[#This Row],[yi]] -> 22104 | C4: ÇALIŞAN | D4: _MUHASEBE | F4: 22104 | G4: 22104 | H4: =SUMIF(bordro[Personel],personelListesiGuncel[[#This Row],[PERSONEL]],bordro[Yİ]) -> 0 | I4: Çalışan | J4: HALİL Y | K4: 55186680706
A5: SÜLEYMAN İP | B5: =personelListesiGuncel[[#This Row],[SGK M.]]+personelListesiGuncel[[#This Row],[yi]] -> 1670 | C5: ÇALIŞAN | D5: _D.ELEMAN | E5: 200 | F5: 48000 | G5: 1670 | H5: =SUMIF(bordro[Personel],personelListesiGuncel[[#This Row],[PERSONEL]],bordro[Yİ]) -> 0 | I5: Çalışan | J5: HALİL Y | K5: 21242693324
A6: ŞENOL DURMUŞ | B6: =personelListesiGuncel[[#This Row],[SGK M.]]+personelListesiGuncel[[#This Row],[yi]] -> 40000 | C6: ÇALIŞAN | D6: _D.ELEMAN | E6: 250 | F6: 52000 | G6: 40000 | H6: =SUMIF(bordro[Personel],personelListesiGuncel[[#This Row],[PERSONEL]],bordro[Yİ]) -> 0 | I6: Çalışan | J6: HALİL Y | K6: 17159801204
A7: CUMA HAVAN | B7: =personelListesiGuncel[[#This Row],[SGK M.]]+personelListesiGuncel[[#This Row],[yi]] -> 22104 | C7: ÇALIŞAN | D7: _D.ELEMAN | F7: 34500 | G7: 22104 | H7: =SUMIF(bordro[Personel],personelListesiGuncel[[#This Row],[PERSONEL]],bordro[Yİ]) -> 0 | I7: Çalışan | J7: HALİL Y | K7: 36826974454
A8: EJDER COŞGUNOĞLU | B8: =personelListesiGuncel[[#This Row],[SGK M.]]+personelListesiGuncel[[#This Row],[yi]] -> 1603 | C8: ÇALIŞAN | D8: _D.ELEMAN | F8: 34500 | G8: 1603 | H8: =SUMIF(bordro[Personel],personelListesiGuncel[[#This Row],[PERSONEL]],bordro[Yİ]) -> 0 | I8: Çalışan | J8: HALİL Y | K8: 17917837216
A9: VEYSEL DUYMAZ | B9: =personelListesiGuncel[[#This Row],[SGK M.]]+personelListesiGuncel[[#This Row],[yi]] -> 2335 | C9: EMEKLİ | D9: _OPERATÖR | E9: 250 | F9: 46000 | G9: 2335 | H9: =SUMIF(bordro[Personel],personelListesiGuncel[[#This Row],[PERSONEL]],bordro[Yİ]) -> 0 | I9: Çalışan | J9: HALİL Y | K9: 23764482950
A10: MUSTAFA KAHRAMAN | B10: =personelListesiGuncel[[#This Row],[SGK M.]]+personelListesiGuncel[[#This Row],[yi]] -> 2000 | C10: ÇALIŞAN | D10: _ŞOFÖR | E10: 200 | F10: 43000 | G10: 2000 | H10: =SUMIF(bordro[Personel],personelListesiGuncel[[#This Row],[PERSONEL]],bordro[Yİ]) -> 0 | I10: Çalışan | J10: HALİL Y | K10: 25672444846
A11: DURSUN ALİ NAZİK | B11: =personelListesiGuncel[[#This Row],[SGK M.]]+personelListesiGuncel[[#This Row],[yi]] -> 35000 | C11: ÇALIŞAN | D11: _MÜHNEDİS | F11: 57500 | G11: 35000 | H11: =SUMIF(bordro[Personel],personelListesiGuncel[[#This Row],[PERSONEL]],bordro[Yİ]) -> 0 | I11: Çalışan | J11: HALİL Y | K11: 51994540164
A12: CİHAN DUYMAZ | B12: =personelListesiGuncel[[#This Row],[SGK M.]]+personelListesiGuncel[[#This Row],[yi]] -> 33000 | C12: ÇALIŞAN | D12: _KANTAR | E12: 200 | F12: 40000 | G12: 33000 | H12: =SUMIF(bordro[Personel],personelListesiGuncel[[#This Row],[PERSONEL]],bordro[Yİ]) -> 0 | I12: Çalışan | J12: HALİL Y | K12: 23713484608
A13: YILMAZ YILMAZ | B13: =personelListesiGuncel[[#This Row],[SGK M.]]+personelListesiGuncel[[#This Row],[yi]] -> 0 | C13: EMEKLİ | D13: _ŞOFÖR | E13: 200 | F13: 40000 | G13: 0 | H13: =SUMIF(bordro[Personel],personelListesiGuncel[[#This Row],[PERSONEL]],bordro[Yİ]) -> 0 | I13: Çıktı | J13: HALİL Y
A14: OSMAN BİLGİN | C14: EMEKLİ | D14: _ŞOFÖR | F14: 40000 | G14: 0 | H14: =SUMIF(bordro[Personel],personelListesiGuncel[[#This Row],[PERSONEL]],bordro[Yİ]) -> 0
A15: MEHMET ALİ ALTINOK | B15: 2333.4 | C15: EMEKLİ | D15: _OPERATÖR | F15: 50000 | G15: 2335 | H15: =SUMIF(bordro[Personel],personelListesiGuncel[[#This Row],[PERSONEL]],bordro[Yİ]) -> 0
A16: ALİM MEDETOĞULLARI | B16: =personelListesiGuncel[[#This Row],[SGK M.]]+personelListesiGuncel[[#This Row],[yi]] -> 15000 | C16: ÇALIŞAN | D16: _TAMİR | E16: 230 | F16: 15000 | G16: 15000 | H16: =SUMIF(bordro[Personel],personelListesiGuncel[[#This Row],[PERSONEL]],bordro[Yİ]) -> 0 | I16: Çalışan | J16: HALİL Y | K16: 14188598600
A17: BEKİR BULUT | B17: =personelListesiGuncel[[#This Row],[SGK M.]]+personelListesiGuncel[[#This Row],[yi]] -> 1603 | C17: EMEKLİ | D17: _OPERATÖR | F17: 50000 | G17: 1603 | K17: 14743821358
A18: ÜMİT YİĞİT | B18: =personelListesiGuncel[[#This Row],[SGK M.]]+personelListesiGuncel[[#This Row],[yi]] -> 11333 | C18: ÇALIŞAN | D18: _OPERATÖR | E18: 250 | F18: 50000 | G18: 11333 | H18: =SUMIF(bordro[Personel],personelListesiGuncel[[#This Row],[PERSONEL]],bordro[Yİ]) -> 0 | I18: Çalışan | J18: HALİL Y | K18: 20743377542
A19: NERMİN ŞEN | B19: =personelListesiGuncel[[#This Row],[SGK M.]]+personelListesiGuncel[[#This Row],[yi]] -> 25000 | C19: ÇALIŞAN | D19: _MUTFAK | E19: 150 | F19: 30000 | G19: 25000 | H19: =SUMIF(bordro[Personel],personelListesiGuncel[[#This Row],[PERSONEL]],bordro[Yİ]) -> 0 | I19: Çalışan | K19: 24235463638
A20: NADİR EROĞLU | B20: =personelListesiGuncel[[#This Row],[SGK M.]]+personelListesiGuncel[[#This Row],[yi]] -> 0 | C20: ÇALIŞAN | D20: _D.ELEMAN | H20: =SUMIF(bordro[Personel],personelListesiGuncel[[#This Row],[PERSONEL]],bordro[Yİ]) -> 0
A21: ENVER İBKİN | B21: =personelListesiGuncel[[#This Row],[SGK M.]]+personelListesiGuncel[[#This Row],[yi]] -> 0 | C21: ÇALIŞAN | D21: _BEKÇİ | F21: 30000 | G21: 0 | H21: =SUMIF(bordro[Personel],personelListesiGuncel[[#This Row],[PERSONEL]],bordro[Yİ]) -> 0
A22: YAŞAR COŞKUN | B22: =personelListesiGuncel[[#This Row],[SGK M.]]+personelListesiGuncel[[#This Row],[yi]] -> 1603 | C22: ÇALIŞAN | D22: _ŞOFÖR | F22: 43000 | G22: 1603 | H22: =SUMIF(bordro[Personel],personelListesiGuncel[[#This Row],[PERSONEL]],bordro[Yİ]) -> 0
A23: HARUN ZEYBEK | B23: =personelListesiGuncel[[#This Row],[SGK M.]]+personelListesiGuncel[[#This Row],[yi]] -> 50000 | C23: ÇALIŞAN | D23: _OPERATÖR | F23: 50000 | G23: 50000 | H23: =SUMIF(bordro[Personel],personelListesiGuncel[[#This Row],[PERSONEL]],bordro[Yİ]) -> 0 | K23: 22118361712
A24: MURAT EROL | B24: =personelListesiGuncel[[#This Row],[SGK M.]]+personelListesiGuncel[[#This Row],[yi]] -> 28000 | C24: ÇALIŞAN | D24: _OPERATÖR | F24: 50000 | G24: 28000 | K24: 51499451514
A25: VOLKAN KATRI | B25: 50000 | C25: ÇALIŞAN | D25: _OPERATÖR | E25: 250 | F25: 50000
A26: AYHAN DOĞRU | B26: =personelListesiGuncel[[#This Row],[SGK M.]]+personelListesiGuncel[[#This Row],[yi]] -> 2335 | C26: ÇALIŞAN | D26: _OPERATÖR | F26: 50000 | G26: 2335
A27: BAYRAM ALSAN | B27: =personelListesiGuncel[[#This Row],[SGK M.]]+personelListesiGuncel[[#This Row],[yi]] -> 34500 | C27: ÇALIŞAN | D27: _OPERATÖR | F27: 34500 | G27: 34500
A28: ARZU DANACI | B28: 0 | C28: ÇALIŞAN | D28: _MUHASEBE | F28: 45000 | G28: 0 | K28: 23965724132
A29: GÜRHAN | B29: 30000 | D29: _AİLE | F29: 30000 | G29: 0 | H29: =SUMIF(bordro[Personel],personelListesiGuncel[[#This Row],[PERSONEL]],bordro[Yİ]) -> 0 | I29: Çalışan
A30: FATMA KOCATÜRK | D30: _AİLE | F30: 30000 | G30: 0
A31: NAFAKA | D31: _AİLE | F31: 13000
A32: ALFİYA FERMAN | B32: =personelListesiGuncel[[#This Row],[SGK M.]]+personelListesiGuncel[[#This Row],[yi]] -> 22104 | C32: ÇALIŞAN | D32: _AİLE | F32: 40000 | G32: 22104 | H32: =SUMIF(bordro[Personel],personelListesiGuncel[[#This Row],[PERSONEL]],bordro[Yİ]) -> 0 | I32: Çalışan | J32: HALİL Y | K32: 74524099796
A33: MELEKNUR YILMAZ | B33: =personelListesiGuncel[[#This Row],[SGK M.]]+personelListesiGuncel[[#This Row],[yi]] -> 30000 | C33: ÇALIŞAN | D33: _AİLE | F33: 50000 | G33: 30000 | H33: 0 | I33: Çıktı | J33: HALİL Y | K33: 64996156028
A34: Dilek TOPAL | B34: =personelListesiGuncel[[#This Row],[SGK M.]]+personelListesiGuncel[[#This Row],[yi]] -> 22104 | C34: ÇALIŞAN | D34: _AİLE | F34: 30000 | G34: 22104 | H34: =SUMIF(bordro[Personel],personelListesiGuncel[[#This Row],[PERSONEL]],bordro[Yİ]) -> 0 | I34: Çalışan | J34: HALİL Y | K34: 18736701092
A35: AJDA OZANER | B35: =personelListesiGuncel[[#This Row],[SGK M.]]+personelListesiGuncel[[#This Row],[yi]] -> 30000 | C35: ÇALIŞAN | D35: _AİLE | F35: 50000 | G35: 30000 | H35: 0 | I35: Çıktı | J35: HALİL Y | K35: 22093575890
A36: AYŞEGÜL OZANER | B36: =personelListesiGuncel[[#This Row],[SGK M.]]+personelListesiGuncel[[#This Row],[yi]] -> 0 | C36: ÇALIŞAN | D36: _AİLE | F36: 30000 | H36: =SUMIF(bordro[Personel],personelListesiGuncel[[#This Row],[PERSONEL]],bordro[Yİ]) -> 0 | I36: Çalışan | J36: HALİL Y | K36: 30148302742
A37: YAHYA-ÖMER | B37: =personelListesiGuncel[[#This Row],[SGK M.]]+personelListesiGuncel[[#This Row],[yi]] -> 0 | C37: ÇALIŞAN | D37: _AİLE | F37: 30000 | G37: 0 | H37: =SUMIF(bordro[Personel],personelListesiGuncel[[#This Row],[PERSONEL]],bordro[Yİ]) -> 0
A38: YAHYA-NAFAKA | B38: 0 | D38: _AİLE | F38: 20000 | G38: 0 | H38: 0

Sheet bordro
B1: YIL | C1: AY | D1: SSK FRM | E1: TC KİMLİK NO | F1: MÜŞT. NO | G1: Sütun1 | H1: Personel | I1: G. Maaş | J1: SGK-BNK | K1: E. | L1: B+E | M1: Eld. [+/-] | N1: Açıklama | O1: Yİ
B2: 2025 | C2: 1 | D2: _MUHASEBE | E2: 28699369338 | F2: 96358353 | G2: part2 | H2: ABDULLAH KARAHANCI | I2: 57500 | J2: 40000 | K2: 5000 | L2: 45000
B3: 2025 | C3: 1 | D3: _D.ELEMAN | E3: 17630785580 | F3: 95529415 | G3: part2 | H3: DURSUN DURMUŞ | I3: 75000 | J3: 2670 | K3: 62330 | L3: 65000
B4: 2025 | C4: 1 | D4: _MUHASEBE | E4: 55186680706 | F4: 95787183 | G4: part2 | H4: RAMAZAN TUNCER | I4: 22104 | J4: 22104 | K4: 0 | L4: 22104
B5: 2025 | C5: 1 | D5: _D.ELEMAN | E5: 21242693324 | F5: 95532064 | G5: Part1 | H5: SÜLEYMAN İP | I5: 48000 | J5: 1670 | K5: 38330 | L5: 40000
B6: 2025 | C6: 1 | D6: _D.ELEMAN | E6: 17159801204 | F6: 95532066 | G6: Part1 | H6: ŞENOL DURMUŞ | I6: 52000 | J6: 40000 | K6: 5000 | L6: 45000
B7: 2025 | C7: 1 | D7: _D.ELEMAN | E7: 36826974454 | F7: 0 | G7: Part1 | H7: CUMA HAVAN | I7: 34500 | J7: 22104 | K7: 12998 | L7: 35102
B8: 2025 | C8: 1 | D8: _D.ELEMAN | E8: 17917837216 | F8: 0 | G8: Part1 | H8: EJDER COŞGUNOĞLU | I8: 34500 | J8: 1603 | K8: 12998 | L8: 14601
B9: 2025 | C9: 1 | D9: _OPERATÖR | E9: 23764482950 | F9: 95532077 | G9: part2 | H9: VEYSEL DUYMAZ | I9: 46000 | J9: 2335 | K9: 37665 | L9: 40000
B10: 2025 | C10: 1 | D10: _ŞOFÖR | E10: 25672444846 | F10: 95693810 | G10: Part1 | H10: MUSTAFA KAHRAMAN | I10: 43000 | J10: 2000 | K10: 35499.9 | L10: 37499.9
B11: 2025 | C11: 1 | D11: _MÜHNEDİS | E11: 51994540164 | F11: 96900867 | G11: part2 | H11: DURSUN ALİ NAZİK | I11: 57500 | J11: 35000 | K11: 13000 | L11: 48000
B12: 2025 | C12: 1 | D12: _KANTAR | E12: 23713484608 | F12: 97189681 | G12: Part1 | H12: CİHAN DUYMAZ | I12: 40000 | J12: 38000 | K12: 0 | L12: 38000
B13: 2025 | C13: 1 | D13: _ŞOFÖR | E13: 0 | F13: 0 | G13: Part1 | H13: OSMAN BİLGİN | I13: 40000 | J13: 0 | K13: 33000 | L13: 33000
B14: 2025 | C14: 1 | D14: _TAMİR | E14: 14188598600 | F14: 0 | G14: Part1 | H14: ALİM MEDETOĞULLARI | I14: 48000 | J14: 48000 | K14: 0 | L14: 48000
B15: 2025 | C15: 1 | D15: _OPERATÖR | E15: 0 | F15: 0 | G15: Part1 | H15: MEHMET ALİ ALTINOK | I15: 50000 | J15: 2335 | K15: 40165 | L15: 42500
B16: 2025 | C16: 1 | D16: _OPERATÖR | E16: 20743377542 | F16: 99029232 | G16: Part1 | H16: ÜMİT YİĞİT | I16: 50000 | J16: 11333 | K16: 0 | L16: 11333
B17: 2025 | C17: 1 | D17: _MUTFAK | E17: 24235463638 | F17: 0 | G17: Part1 | H17: NERMİN ŞEN | I17: 30000 | J17: 25000 | K17: 0 | L17: 25000
B18: 2025 | C18: 1 | D18: _D.ELEMAN | E18: 0 | F18: 0 | G18: Part1 | H18: NADİR EROĞLU | I18: 0 | J18: 0 | K18: 6000 | L18: 6000
B19: 2025 | C19: 1 | D19: _BEKÇİ | E19: 0 | F19: 0 | G19: Part1 | H19: ENVER İBKİN | I19: 30000 | J19: 0 | K19: 25000 | L19: 25000
B20: 2025 | C20: 1 | D20: _ŞOFÖR | E20: 0 | F20: 0 | G20: Part1 | H20: YILMAZ YILMAZ | I20: 11920 | J20: 0 | K20: 30999.9 | L20: 30999.9
B21: 2025 | C21: 1 | D21: _ŞOFÖR | E21: 0 | F21: 0 | G21: Part1 | H21: YAŞAR COŞKUN | I21: 43000 | J21: 1603 | K21: 33000 | L21: 34603
B22: 2025 | C22: 1 | D22: 0 | E22: 0 | F22: 0 | G22: part2 | H22: SAMET EROĞLU | I22: 15000 | J22: 0 | K22: 15000 | L22: 15000
B23: 2025 | C23: 1 | D23: _OPERATÖR | E23: 22118361712 | F23: 0 | G23: Part1 | H23: HARUN ZEYBEK | I23: 50000 | J23: 30000 | K23: 2833.33 | L23: 32833.33
B24: 2025 | C24: 1 | D24: _AİLE | E24: 18736701092 | F24: 95547779 | G24: part2 | H24: Dilek TOPAL | I24: 30000 | J24: 22104 | K24: 12998 | L24: 35102
B25: 2025 | C25: 1 | D25: _AİLE | E25: 74524099796 | F25: 98127163 | G25: part2 | H25: ALFİYA FERMAN | I25: 40000 | J25: 22104 | K25: -2 | L25: 22102
B26: 2025 | C26: 1 | D26: _AİLE | E26: 0 | F26: 0 | G26: part2 | H26: YAHYA-ÖMER | I26: 30000 | J26: 0 | K26: 30000 | L26: 30000
B27: 2025 | C27: 1 | D27: _AİLE | E27: 22093575890 | F27: 96260905 | G27: part2 | H27: AJDA OZANER | I27: 50000 | J27: 30000 | K27: 50000 | L27: 80000
B28: 2025 | C28: 1 | D28: _AİLE | E28: 64996156028 | F28: 95539771 | G28: part2 | H28: MELEKNUR YILMAZ | I28: 50000 | J28: 30000 | K28: 50000 | L28: 80000
B29: 2025 | C29: 2 | D29: _MUHASEBE | E29: 28699369338 | F29: 96358353 | G29: e | H29: ABDULLAH KARAHANCI | I29: 57500 | J29: 40000 | K29: 17500 | L29: 57500
B30: 2025 | C30: 2 | D30: _D.ELEMAN | E30: 17630785580 | F30: 95529415 | G30: bnk | H30: DURSUN DURMUŞ | I30: 75000 | J30: 2670 | K30: 72330 | L30: 75000
B31: 2025 | C31: 2 | D31: _MUHASEBE | E31: 55186680706 | F31: 95787183 | G31: bnk | H31: RAMAZAN TUNCER | I31: 22104 | J31: 22104 | K31: 0 | L31: 22104
B32: 2025 | C32: 2 | D32: _D.ELEMAN | E32: 21242693324 | F32: 95532064 | G32: bnk | H32: SÜLEYMAN İP | I32: 48000 | J32: 1670 | K32: 46330 | L32: 48000
B33: 2025 | C33: 2 | D33: _D.ELEMAN | E33: 17159801204 | F33: 95532066 | G33: bnk | H33: ŞENOL DURMUŞ | I33: 52000 | J33: 40000 | K33: 12000 | L33: 52000
B34: 2025 | C34: 2 | D34: _D.ELEMAN | E34: 36826974454 | F34: 0 | G34: bnk | H34: CUMA HAVAN | I34: 34500 | J34: 22104 | K34: 12396 | L34: 34500
B35: 2025 | C35: 2 | D35: _D.ELEMAN | E35: 17917837216 | F35: 0 | G35: bnk | H35: EJDER COŞGUNOĞLU | I35: 34500 | J35: 1603 | K35: 32897 | L35: 34500
B36: 2025 | C36: 2 | D36: _OPERATÖR | E36: 23764482950 | F36: 95532077 | G36: bnk | H36: VEYSEL DUYMAZ | I36: 46000 | J36: 2335 | K36: 43665 | L36: 46000
B37: 2025 | C37: 2 | D37: _ŞOFÖR | E37: 25672444846 | F37: 95693810 | G37: bnk | H37: MUSTAFA KAHRAMAN | I37: 43000 | J37: 2000 | K37: 41000 | L37: 43000
B38: 2025 | C38: 2 | D38: _MÜHNEDİS | E38: 51994540164 | F38: 96900867 | G38: bnk | H38: DURSUN ALİ NAZİK | I38: 57500 | J38: 35000 | K38: 22500 | L38: 57500
B39: 2025 | C39: 2 | D39: _KANTAR | E39: 23713484608 | F39: 97189681 | G39: bnk | H39: CİHAN DUYMAZ | I39: 40000 | J39: 38000 | K39: 2000 | L39: 40000
B40: 2025 | C40: 2 | D40: _ŞOFÖR | E40: 0 | F40: 0 | G40: e | H40: OSMAN BİLGİN | I40: 40000 | J40: 0 | K40: 40000 | L40: 40000
...

Sheet bordro (2024)
B1: YIL | C1: AY | D1: SSK FRM | E1: TC KİMLİK NO | F1: MÜŞT. NO | G1: Sütun1 | H1: Personel | I1: G. Maaş | J1: SGK-BNK | K1: E. | L1: B+E | M1: Eld. [+/-] | N1: Açıklama | O1: Yİ
B2: 2024 | C2: 1 | D2: _MUHASEBE | E2: 28699369338 | F2: 96358353 | G2: 1 | H2: ABDULLAH KARAHANCI | I2: 40000 | J2: 40000 | K2: 0 | L2: 40000
B3: 2024 | C3: 1 | D3: _D.ELEMAN | E3: 36826974454 | F3: 95573006 | G3: 1 | H3: CUMA HAVAN | I3: 17002 | J3: 17002 | K3: 0 | L3: 17002
B4: 2024 | C4: 1 | D4: _D.ELEMAN | E4: 17630785580 | F4: 95529415 | G4: 1 | H4: DURSUN DURMUŞ | I4: 87000 | J4: 40000 | K4: 47000 | L4: 87000
B5: 2024 | C5: 1 | D5: _MUHASEBE | E5: 55186680706 | F5: 95787183 | G5: 1 | H5: RAMAZAN TUNCER | I5: 17002 | J5: 17002 | K5: 0 | L5: 17002
B6: 2024 | C6: 1 | D6: _D.ELEMAN | E6: 21242693324 | F6: 95532064 | G6: 1 | H6: SÜLEYMAN İP | I6: 25000 | J6: 25000 | K6: 0 | L6: 25000
B7: 2024 | C7: 1 | D7: _D.ELEMAN | E7: 17159801204 | F7: 95532066 | G7: 1 | H7: ŞENOL DURMUŞ | I7: 35000 | J7: 35000 | K7: 0 | L7: 35000
B8: 2024 | C8: 1 | D8: _OPERATÖR | E8: 23764482950 | F8: 95532077 | G8: 1 | H8: VEYSEL DUYMAZ | I8: 25000 | J8: 25000 | K8: 0 | L8: 25000 | N8: AVANS KESİNTİSİ 10000
B9: 2024 | C9: 1 | D9: _ŞOFÖR | E9: 25672444846 | F9: 95693810 | G9: 1 | H9: MUSTAFA KAHRAMAN | I9: 30000 | J9: 30000 | K9: 0 | L9: 30000
B10: 2024 | C10: 1 | D10: _OPERATÖR | E10: 33853146700 | F10: 96959868 | G10: 1 | H10: MEHMET ALİ ALTINOK | I10: 35000 | J10: 35000 | K10: 0 | L10: 35000
B11: 2024 | C11: 1 | D11: _MÜHNEDİS | E11: 51994540164 | F11: 96900867 | G11: 1 | H11: DURSUN ALİ NAZİK | I11: 35000 | J11: 35000 | K11: 0 | L11: 35000
B12: 2024 | C12: 1 | D12: _KANTAR | E12: 23713484608 | F12: 97189681 | G12: 1 | H12: CİHAN DUYMAZ | I12: 30000 | J12: 30000 | K12: 0 | L12: 30000
B13: 2024 | C13: 1 | D13: _D.ELEMAN | E13: 17891875174 | F13: 6214238 | G13: 1 | H13: OSMAN KAYALI | I13: 17002 | J13: 17002 | K13: 0 | L13: 17002
B14: 2024 | C14: 1 | D14: _OPERATÖR | E14: 38233125580 | F14: 95532065 | G14: 1 | H14: SERCAN BARDAKCI | I14: 37500 | J14: 37500 | K14: 0 | L14: 37500
B15: 2024 | C15: 1 | D15: _AİLE | E15: 18736701092 | F15: 95547779 | G15: 1 | H15: FATMA KOCATÜRK | I15: 30000 | J15: 17002 | K15: 12998 | L15: 30000
B16: 2024 | C16: 1 | D16: _çaycı | E16: 0 | F16: 0 | G16: 0 | H16: ŞİNASİ VURAL POLAT | I16: 18685 | J16: 0 | K16: 18685 | L16: 18685
B17: 2024 | C17: 1 | D17: _ŞOFÖR | E17: 29107341298 | F17: 0 | G17: 0 | H17: MUSTAFA KARADEMİR | I17: 29000 | J17: 0 | K17: 29000 | L17: 29000 | N17: 1 gün eksik
B18: 2024 | C18: 1 | D18: _ŞOFÖR | E18: 10459950610 | F18: 97226520 | G18: 1 | H18: EMRULLAH BOZ | I18: 30000 | J18: 30000 | K18: 0 | L18: 30000
B19: 2024 | C19: 1 | D19: _OPERATÖR | E19: 63097169876 | F19: 96843148 | G19: 1 | H19: AYHAN DOĞRU | I19: 35000 | J19: 35000 | K19: 0 | L19: 35000
B20: 2024 | C20: 1 | D20: _BEKÇİ | E20: 0 | F20: 0 | G20: 0 | H20: KADİR BEKÇİ | I20: 20000 | J20: 0 | K20: 15000 | L20: 15000 | M20: -5000 | N20: AVANS KESİNTİSİ
B21: 2024 | C21: 1 | D21: _MUHASEBE | E21: 18727701384 | F21: 98682849 | G21: 1 | H21: BURAK KOCATÜRK | I21: 32500 | J21: 32500 | K21: 0 | L21: 32500
B22: 2024 | C22: 1 | D22: _MUHASEBE | E22: 24293051488 | F22: 98751426 | G22: 1 | H22: SALİH GÜNGÖR | I22: 6234 | J22: 6234 | K22: 0 | L22: 6234
B23: 2024 | C23: 1 | D23: _ŞOFÖR | E23: 0 | F23: 0 | G23: 0 | H23: OSMAN BİLGİN | I23: 30000 | J23: 0 | K23: 30000 | L23: 30000
B24: 2024 | C24: 1 | D24: _ŞOFÖR | E24: 0 | F24: 0 | G24: 0 | H24: YILMAZ YILMAZ | I24: 30000 | J24: 0 | K24: 31000 | L24: 31000 | M24: 1000 | N24: soför payı
B25: 2024 | C25: 1 | D25: _TAMİR | E25: 14188598600 | F25: 0 | G25: 0 | H25: ALİM MEDETOĞULLARI | I25: 35000 | J25: 0 | K25: 35000 | L25: 35000
B26: 2024 | C26: 1 | D26: _OPERATÖR | E26: 20743377542 | F26: 99029232 | G26: 1 | H26: ÜMİT YİĞİT | I26: 36250 | J26: 36250 | K26: 0 | L26: 36250 | N26: 1 gün eksik
B27: 2024 | C27: 1 | D27: _AİLE | E27: 74524099796 | F27: 98127163 | G27: 1 | H27: ALFİYA FERMAN | I27: 30000 | J27: 17002 | K27: 12998 | L27: 30000
B28: 2024 | C28: 1 | D28: _AİLE | E28: 22093575890 | F28: 96260905 | G28: 1 | H28: AJDA OZANER | I28: 30000 | J28: 30000 | K28: 0 | L28: 30000
B29: 2024 | C29: 1 | D29: _AİLE | E29: 30148302742 | F29: 97726066 | G29: 1 | H29: AYŞEGÜL OZANER | I29: 17002 | J29: 17002 | K29: 0 | L29: 17002
B30: 2024 | C30: 1 | D30: _AİLE | E30: 64996156028 | F30: 95539771 | G30: 1 | H30: MELEKNUR YILMAZ | I30: 30000 | J30: 30000 | K30: 0 | L30: 30000
B31: 2024 | C31: 1 | D31: _AİLE | E31: 0 | F31: 0 | G31: 0 | H31: YAHYA-ÖMER | I31: 15000 | J31: 0 | K31: 15000 | L31: 15000
B32: 2024 | C32: 1 | D32: _AİLE | E32: 0 | F32: 0 | G32: 0 | H32: YAHYA-NAFAKA | I32: 20000 | J32: 0 | K32: 20000 | L32: 11000
B33: 2024 | C33: 2 | D33: _MUHASEBE | E33: 28699369338 | F33: 96358353 | G33: 1 | H33: ABDULLAH KARAHANCI | I33: 40000 | J33: 40000 | K33: 0 | L33: 40000
B34: 2024 | C34: 2 | D34: _D.ELEMAN | E34: 36826974454 | F34: 95573006 | G34: 1 | H34: CUMA HAVAN | I34: 17002 | J34: 17002 | K34: 0 | L34: 17002
B35: 2024 | C35: 2 | D35: _D.ELEMAN | E35: 17630785580 | F35: 95529415 | G35: 1 | H35: DURSUN DURMUŞ | I35: 87000 | J35: 40000 | K35: 47000 | L35: 87000
B36: 2024 | C36: 2 | D36: _MUHASEBE | E36: 55186680706 | F36: 95787183 | G36: 1 | H36: RAMAZAN TUNCER | I36: 17002 | J36: 17002 | K36: 0 | L36: 17002
B37: 2024 | C37: 2 | D37: _D.ELEMAN | E37: 21242693324 | F37: 95532064 | G37: 1 | H37: SÜLEYMAN İP | I37: 25000 | J37: 25000 | K37: 0 | L37: 25000
B38: 2024 | C38: 2 | D38: _D.ELEMAN | E38: 17159801204 | F38: 95532066 | G38: 1 | H38: ŞENOL DURMUŞ | I38: 35000 | J38: 35000 | K38: 0 | L38: 35000
B39: 2024 | C39: 2 | D39: _OPERATÖR | E39: 23764482950 | F39: 95532077 | G39: 1 | H39: VEYSEL DUYMAZ | I39: 25000 | J39: 25000 | K39: 0 | L39: 25000 | N39: 10,000 avans kesintisi
B40: 2024 | C40: 2 | D40: _ŞOFÖR | E40: 25672444846 | F40: 95693810 | G40: 1 | H40: MUSTAFA KAHRAMAN | I40: 28000 | J40: 28000 | K40: 0 | L40: 28000
...

Sheet bordro_2023_
B1: YIL | C1: AY | D1: SSK FRM | E1: TC KİMLİK NO | F1: MÜŞT. NO | G1: EK | H1: Personel | I1: BANKA | J1: G. Maaş | K1: SGK-BNK | L1: E. | M1: B+E | N1: Eld. [+/-] | O1: Açıklama | P1: Bnk. Avans/Rapor | Q1: Eks.Gün | R1: Yİ | S1: Açıklama2
B2: 2021 | C2: 1 | D2: HALİL Y | E2: 28699369338 | F2: 96358353 | G2: 1 | H2: ABDULLAH KARAHANCI | I2: 3350 | J2: 3350 | K2: 3350 | L2: 0 | M2: 3350
B3: 2021 | C3: 1 | D3: HALİL Y | E3: 63097169876 | F3: 96843148 | G3: 1 | H3: AYHAN DOĞRU | I3: 547 | J3: 4000 | K3: 547 | L3: 3453 | M3: 4000 | Q3: 25
B4: 2021 | C4: 1 | D4: HALİL Y | E4: 36826974454 | F4: 95573006 | G4: 1 | H4: CUMA HAVAN | I4: 3013.72 | J4: 3013.72 | K4: 3013.72 | L4: 0 | M4: 3013.72
B5: 2021 | C5: 1 | D5: HALİL Y | E5: 17630785580 | F5: 95529415 | G5: 1 | H5: DURSUN DURMUŞ | I5: 3188.13 | J5: 7188.13 | K5: 3188.13 | L5: 4000 | M5: 7188.13
B6: 2021 | C6: 1 | D6: HALİL Y | E6: 27172394690 | F6: 95702622 | G6: 1 | H6: KERİM ŞİMŞEK | I6: 3300 | J6: 3300.03 | K6: 3300 | L6: 0.03 | M6: 3300.03
B7: 2021 | C7: 1 | D7: HALİL Y | E7: 64996156028 | F7: 95539771 | G7: 1 | H7: MELEKNUR YILMAZ | I7: 2825.9 | J7: 2825.9 | K7: 2825.9 | L7: 0 | M7: 2825.9
B8: 2021 | C8: 1 | D8: HALİL Y | E8: 59233322526 | F8: 96712272 | G8: 1 | H8: ORHAN UZUN | I8: 2216.83 | J8: 2216.83 | K8: 2216.83 | L8: -1000 | M8: 1216.83 | N8: -1000 | P8: -1283.17 | Q8: 4
B9: 2021 | C9: 1 | D9: HALİL Y | E9: 55186680706 | F9: 95787183 | G9: 1 | H9: RAMAZAN TUNCER | I9: 1530.4 | J9: 5000 | K9: 1530.4 | L9: 3469.6 | M9: 5000
B10: 2021 | C10: 1 | D10: HALİL Y | E10: 21242693324 | F10: 95532064 | G10: 1 | H10: SÜLEYMAN İP | I10: 2825.9 | J10: 2825.9 | K10: 2825.9 | L10: 0 | M10: 2825.9
B11: 2021 | C11: 1 | D11: HALİL Y | E11: 17159801204 | F11: 95532066 | G11: 1 | H11: ŞENOL DURMUŞ | I11: 2919.81 | J11: 2919.81 | K11: 2919.81 | L11: 0 | M11: 2919.81
B12: 2021 | C12: 1 | D12: HALİL Y | E12: 66385338732 | F12: 96717247 | G12: 1 | H12: ŞİRİN GENCE | I12: 2825.9 | J12: 2825.9 | K12: 2825.9 | L12: 0 | M12: 2825.9
B13: 2021 | C13: 1 | D13: HALİL Y | E13: 23764482950 | F13: 95532077 | G13: 1 | H13: VEYSEL DUYMAZ | I13: 547 | J13: 3300 | K13: 547 | L13: 2253 | M13: 2800 | N13: -500 | Q13: 25 | R13: 1
B14: 2021 | C14: 1 | D14: Y KUM | E14: 18274523170 | F14: 95532068 | G14: 1 | H14: BEKİR TAŞÇILAR | I14: 547 | J14: 3300 | K14: 547 | L14: 2753 | M14: 3300 | Q14: 25 | R14: 3
B15: 2021 | C15: 1 | D15: Y KUM | E15: 25672444846 | F15: 95693810 | G15: 1 | H15: MUSTAFA KARAMAN | I15: 3300 | J15: 3300 | K15: 3300 | L15: 0 | M15: 3300
B16: 2021 | C16: 1 | D16: Y KUM | E16: 39617231002 | F16: 95532072 | G16: 1 | H16: RÜSTEM ÜLFEM | I16: 3300 | J16: 3300 | K16: 3300 | L16: 0 | M16: 3300 | R16: 3
B17: 2021 | C17: 1 | D17: Y KUM | E17: 15394555838 | F17: 95580195 | G17: 1 | H17: YILMAZ YILMAZ | I17: 547 | J17: 3300 | K17: 547 | L17: 2753 | M17: 3300 | Q17: 25
B18: 2021 | C18: 1 | D18: Y KUM | E18: 14084651324 | F18: 96100644 | G18: 1 | H18: ÇETİN ERGİN | I18: 2825.9 | J18: 2825.9 | K18: 2825.9 | L18: 0 | M18: 2825.9 | N18: 0 | O18: Sonraki aya 150 tl avans devir | S18: Sonraki aya 150 tl avans devir
B19: 2021 | C19: 1 | D19: Y KUM | E19: 36133121404 | F19: 94985817 | G19: 1 | H19: ÖMER KÖROĞLU | I19: 2825.9 | J19: 6000 | K19: 2825.9 | L19: 3174.1 | M19: 6000
B20: 2021 | C20: 1 | D20: HALİL Y | E20: 33853146700 | F20: 96959868 | G20: 1 | H20: MEHMET ALİ ALTIOK | I20: 547 | J20: 4000 | K20: 547 | L20: 3453 | M20: 4000 | Q20: 25
B21: 2021 | C21: 1 | D21: HALİL Y | E21: 51994540164 | F21: 96900867 | G21: 1 | H21: DURSUN ALİ NAZİK | I21: 2825.9 | J21: 2825.9 | K21: 2825.9 | L21: 0 | M21: 2825.9
B22: 2021 | C22: 1 | D22: HALİL Y | E22: 52657562356 | F22: 97011710 | G22: 1 | H22: EMRE SÖNMEZ | I22: 2825.9 | J22: 2825.9 | K22: 2825.9 | L22: 0 | M22: 2825.9
B23: 2021 | C23: 1 | D23: HALİL Y | E23: 34324181220 | F23: 95529414 | G23: 1 | H23: İBRAHİM AKYOL | I23: 2131.82 | J23: 2131.82 | K23: 2131.82 | L23: 0 | M23: 2131.82
B24: 2021 | C24: 2 | D24: HALİL Y | E24: 28699369338 | F24: 96358353 | G24: 1 | H24: ABDULLAH KARAHANCI | I24: 3350 | J24: 3350 | K24: 3350 | L24: 0 | M24: 3350
B25: 2021 | C25: 2 | D25: HALİL Y | E25: 63097169876 | F25: 96843148 | G25: 1 | H25: AYHAN DOĞRU | I25: 547 | J25: 4000 | K25: 547 | L25: 3453 | M25: 4000 | Q25: 25
B26: 2021 | C26: 2 | D26: HALİL Y | E26: 36826974454 | F26: 95573006 | G26: 1 | H26: CUMA HAVAN | I26: 3013.72 | J26: 3013.72 | K26: 3013.72 | L26: 0 | M26: 3013.72
B27: 2021 | C27: 2 | D27: HALİL Y | E27: 17630785580 | F27: 95529415 | G27: 1 | H27: DURSUN DURMUŞ | I27: 3188.13 | J27: 7188.13 | K27: 3188.13 | L27: 4000 | M27: 7188.13
B28: 2021 | C28: 2 | D28: HALİL Y | E28: 27172394690 | F28: 95702622 | G28: 1 | H28: KERİM ŞİMŞEK | I28: 2548 | J28: 2548.03 | K28: 2548 | L28: 0.03 | M28: 2548.03 | P28: -752
B29: 2021 | C29: 2 | D29: HALİL Y | E29: 64996156028 | F29: 95539771 | G29: 1 | H29: MELEKNUR YILMAZ | I29: 2825.9 | J29: 2825.9 | K29: 2825.9 | L29: 0 | M29: 2825.9
B30: 2021 | C30: 2 | D30: HALİL Y | E30: 59233322526 | F30: 96712272 | G30: 1 | H30: ORHAN UZUN | I30: 3500 | J30: 3500 | K30: 3500 | L30: 0 | M30: 3500
B31: 2021 | C31: 2 | D31: HALİL Y | E31: 55186680706 | F31: 95787183 | G31: 1 | H31: RAMAZAN TUNCER | I31: 1530.4 | J31: 5000 | K31: 1530.4 | L31: 3469.6 | M31: 5000
B32: 2021 | C32: 2 | D32: HALİL Y | E32: 21242693324 | F32: 95532064 | G32: 1 | H32: SÜLEYMAN İP | I32: 2825.9 | J32: 2825.9 | K32: 2825.9 | L32: 0 | M32: 2825.9
B33: 2021 | C33: 2 | D33: HALİL Y | E33: 17159801204 | F33: 95532066 | G33: 1 | H33: ŞENOL DURMUŞ | I33: 2919.81 | J33: 2919.81 | K33: 2919.81 | L33: 0 | M33: 2919.81
B34: 2021 | C34: 2 | D34: HALİL Y | E34: 66385338732 | F34: 96717247 | G34: 1 | H34: ŞİRİN GENCE | I34: 2825.9 | J34: 2825.9 | K34: 2825.9 | L34: 0 | M34: 2825.9
B35: 2021 | C35: 2 | D35: HALİL Y | E35: 23764482950 | F35: 95532077 | G35: 1 | H35: VEYSEL DUYMAZ | I35: 547 | J35: 3300 | K35: 547 | L35: 2753 | M35: 3300 | Q35: 25
B36: 2021 | C36: 2 | D36: Y KUM | E36: 18274523170 | F36: 95532068 | G36: 1 | H36: BEKİR TAŞÇILAR | I36: 547 | J36: 3300 | K36: 547 | L36: 2753 | M36: 3300 | Q36: 25
B37: 2021 | C37: 2 | D37: Y KUM | E37: 25672444846 | F37: 95693810 | G37: 1 | H37: MUSTAFA KARAMAN | I37: 3300 | J37: 3300 | K37: 3300 | L37: 0 | M37: 3300
B38: 2021 | C38: 2 | D38: Y KUM | E38: 39617231002 | F38: 95532072 | G38: 1 | H38: RÜSTEM ÜLFEM | I38: 3300 | J38: 3300 | K38: 3300 | L38: 0 | M38: 3300
B39: 2021 | C39: 2 | D39: Y KUM | E39: 15394555838 | F39: 95580195 | G39: 1 | H39: YILMAZ YILMAZ | I39: 547 | J39: 3300 | K39: 547 | L39: 2753 | M39: 3300 | Q39: 25
B40: 2021 | C40: 2 | D40: Y KUM | E40: 14084651324 | F40: 96100644 | G40: 1 | H40: ÇETİN ERGİN | I40: 2825.9 | J40: 2825.9 | K40: 2825.9 | L40: 350 | M40: 3175.9 | N40: 350
...

Sheet Aylık Bordro Özet
A1: YIL | B1: - all -
A3: AY | B3: Toplam G. Maaş
A4: 1 | B4: 1078024
A5: 2 | B5: 1188024
A6: 3 | B6: 1232024
A7: 4 | B7: 1204024
A8: 5 | B8: 1203104
A9: 6 | B9: 1073104
A10: 7 | B10: 1178437
A11: 8 | B11: 1192604
A12: (empty)
A13: Total Result | B13: 9349345

Sheet Avans Takip
B1: T.Avans: | C1: =SUBTOTAL(109,#REF!) -> #REF! | D1: T.Alınan: | E1: =SUBTOTAL(109,#REF!) -> #REF! | F1: Bakiye: | G1: =C1-E1 -> #REF!
A2: Tarih | B2: Personel | C2: İşlem | D2: Avans | E2: Kesinti | F2: Açıklama | G2: Per. Bakiye
A3: 44511 | B3: MEHMET ALİ ALTIOK | C3: Avans | D3: 3624 | G3: =SUMIF(#REF!,#REF!,D$3:D3)-SUMIF(#REF!,#REF!,E$3:E3) -> #REF!
A4: 44520 | B4: MEHMET ALİ ALTIOK | C4: Avans | D4: 2000 | G4: =SUMIF(#REF!,#REF!,D$3:D4)-SUMIF(#REF!,#REF!,E$3:E4) -> #REF!
A5: 44522 | B5: MEHMET ALİ ALTIOK | C5: Avans | D5: 2000 | G5: =SUMIF(#REF!,#REF!,D$3:D5)-SUMIF(#REF!,#REF!,E$3:E5) -> #REF!
A6: 44515 | B6: MESUT ÇAVDAR | C6: Avans | D6: 5000 | G6: =SUMIF(#REF!,#REF!,D$3:D6)-SUMIF(#REF!,#REF!,E$3:E6) -> #REF!
A7: 44530 | B7: MESUT ÇAVDAR | C7: Avans | D7: 550 | G7: =SUMIF(#REF!,#REF!,D$3:D7)-SUMIF(#REF!,#REF!,E$3:E7) -> #REF!
A8: 44533 | B8: MEHMET ALİ ALTIOK | C8: Kesilen | E8: 600 | G8: =SUMIF(#REF!,#REF!,D$3:D8)-SUMIF(#REF!,#REF!,E$3:E8) -> #REF!
A9: 44912 | B9: ABDULLAH KARAHANCI | C9: Avans | D9: 5000 | G9: =SUMIF(#REF!,#REF!,D$3:D9)-SUMIF(#REF!,#REF!,E$3:E9) -> #REF!
A10: 44905 | B10: KERİM ŞİMŞEK | C10: Avans | D10: 500 | G10: =SUMIF(#REF!,#REF!,D$3:D10)-SUMIF(#REF!,#REF!,E$3:E10) -> #REF!
A11: 44567 | B11: KERİM ŞİMŞEK | C11: Kesilen | E11: 500 | G11: =SUMIF(#REF!,#REF!,D$3:D35)-SUMIF(#REF!,#REF!,E$3:E35) -> #REF!
A12: 44567 | B12: MEHMET ALİ ALTIOK | C12: Kesilen | E12: 1000 | G12: =SUMIF(#REF!,#REF!,D$3:D12)-SUMIF(#REF!,#REF!,E$3:E12) -> #REF!
A13: 44567 | B13: MESUT ÇAVDAR | C13: Kesilen | E13: 1000 | G13: =SUMIF(#REF!,#REF!,D$3:D13)-SUMIF(#REF!,#REF!,E$3:E13) -> #REF!
A14: 44593 | B14: MEHMET ALİ ALTIOK | C14: Kesilen | E14: 1000 | G14: =SUMIF(#REF!,#REF!,D$3:D14)-SUMIF(#REF!,#REF!,E$3:E14) -> #REF!
A15: 44593 | B15: MESUT ÇAVDAR | C15: Kesilen | E15: 1550 | G15: =SUMIF(#REF!,#REF!,D$3:D35)-SUMIF(#REF!,#REF!,E$3:E35) -> #REF!
A16: 44681 | B16: MEHMET ALİ ALTIOK | C16: Kesilen | E16: 1024 | G16: =SUMIF(#REF!,#REF!,D$3:D16)-SUMIF(#REF!,#REF!,E$3:E16) -> #REF!
A17: 44711 | B17: MEHMET ALİ ALTIOK | C17: Kesilen | E17: 1000 | G17: =SUMIF(#REF!,#REF!,D$3:D17)-SUMIF(#REF!,#REF!,E$3:E17) -> #REF!
A18: 44742 | B18: MEHMET ALİ ALTIOK | C18: Kesilen | E18: 1000 | G18: =SUMIF(#REF!,#REF!,D$3:D18)-SUMIF(#REF!,#REF!,E$3:E18) -> #REF!
A19: 44763 | B19: MEHMET ALİ ALTIOK | C19: Avans | D19: 1000 | G19: =SUMIF(#REF!,#REF!,D$3:D19)-SUMIF(#REF!,#REF!,E$3:E19) -> #REF!
A20: 44772 | B20: MEHMET ALİ ALTIOK | C20: Kesilen | E20: 1000 | G20: =SUMIF(#REF!,#REF!,D$3:D35)-SUMIF(#REF!,#REF!,E$3:E35) -> #REF!
A21: 44803 | B21: MEHMET ALİ ALTIOK | E21: 1000 | G21: =SUMIF(#REF!,#REF!,D$3:D21)-SUMIF(#REF!,#REF!,E$3:E21) -> #REF!
A22: 44805 | B22: MELİK KAHRAMAN | C22: Avans | D22: 2600 | G22: =SUMIF(#REF!,#REF!,D$3:D22)-SUMIF(#REF!,#REF!,E$3:E22) -> #REF!
A23: 44809 | B23: MELİK KAHRAMAN | C23: Kesilen | E23: 2600 | G23: =SUMIF(#REF!,#REF!,D$3:D23)-SUMIF(#REF!,#REF!,E$3:E23) -> #REF!
A24: 44927 | B24: MEHMET ALİ ALTIOK | C24: Kesilen | E24: 1000 | G24: =SUMIF(#REF!,#REF!,D$3:D24)-SUMIF(#REF!,#REF!,E$3:E24) -> #REF!
A25: 44931 | B25: KADİR BEKÇİ | C25: Avans | D25: 10000 | G25: =SUMIF(#REF!,#REF!,D$3:D25)-SUMIF(#REF!,#REF!,E$3:E25) -> #REF!
A26: 44960 | B26: KADİR BEKÇİ | C26: Kesilen | E26: 2000 | G26: =SUMIF(#REF!,#REF!,D$3:D26)-SUMIF(#REF!,#REF!,E$3:E26) -> #REF!
A27: 44992 | B27: KADİR BEKÇİ | C27: Kesilen | E27: 2000 | G27: =SUMIF(#REF!,#REF!,D$3:D27)-SUMIF(#REF!,#REF!,E$3:E27) -> #REF!
A28: 44972 | B28: MEHMET ALİ ALTIOK | C28: Avans | D28: 7000 | G28: =SUMIF(#REF!,#REF!,D$3:D35)-SUMIF(#REF!,#REF!,E$3:E35) -> #REF!
A29: 44984 | B29: MEHMET ALİ ALTIOK | C29: Avans | D29: 5000 | G29: =SUMIF(#REF!,#REF!,D$3:D29)-SUMIF(#REF!,#REF!,E$3:E29) -> #REF!
A30: 44992 | B30: MEHMET ALİ ALTIOK | C30: Kesilen | E30: 1000 | G30: =SUMIF(#REF!,#REF!,D$3:D30)-SUMIF(#REF!,#REF!,E$3:E30) -> #REF!
A31: 45019 | B31: MEHMET ALİ ALTIOK | C31: Kesilen | E31: 2000 | G31: =SUMIF(#REF!,#REF!,D$3:D31)-SUMIF(#REF!,#REF!,E$3:E31) -> #REF!
A32: 45019 | B32: KADİR BEKÇİ | C32: Kesilen | E32: 2000 | G32: =SUMIF(#REF!,#REF!,D$3:D32)-SUMIF(#REF!,#REF!,E$3:E32) -> #REF!
G33: =SUMIF(#REF!,#REF!,D$3:D33)-SUMIF(#REF!,#REF!,E$3:E33) -> #REF!
G34: =SUMIF(#REF!,#REF!,D$3:D34)-SUMIF(#REF!,#REF!,E$3:E34) -> #REF!
G35: =SUMIF(#REF!,#REF!,D$3:D35)-SUMIF(#REF!,#REF!,E$3:E35) -> #REF!
D36: =SUBTOTAL(109,#REF!) -> #REF! | E36: =SUBTOTAL(109,#REF!) -> #REF! | F36: =#REF!-#REF! -> #REF!

Sheet MesaiRapor2
A1: ay | B1: - all -
A2: grp | B2: - multiple -
A3: İşlem | B3: Mesai
A5: Tarih | B5: Gün | C5: Personel | D5: Açıklama | E5: Saat | F5: S.Ücret | G5: T. Tutar
A6: 45690 | B6: ADMS | C6: ŞENOL DURMUŞ | D6: PAZAR MESAİ | E6: 10 | F6: 250 | G6: 2500
C7: CUMA HAVAN | D7: PAZAR MESAİ | E7: 10 | F7: 150 | G7: 1500
A8: 45692 | B8: ADMS | C8: SÜLEYMAN İP | D8: HAFTA İÇİ 2 SAAT SALI | E8: 2 | F8: 200 | G8: 400
C9: CUMA HAVAN | D9: HAFTA İÇİ 2 SAAT SALI | E9: 2 | F9: 150 | G9: 300
A10: 45698 | B10: ADMS | C10: SÜLEYMAN İP | D10: HAFTA İÇİ 2 SAAT PAZARTESİ | E10: 2 | F10: 230 | G10: 460
C11: EJDER COŞGUNOĞLU | D11: HAFTA İÇİ 2 SAAT PAZARTESİ | E11: 2 | F11: 150 | G11: 300
A12: 45699 | B12: ADMS | C12: ŞENOL DURMUŞ | D12: HAFTA İÇİ 2 SAAT SALI | E12: 2 | F12: 250 | G12: 500
C13: CUMA HAVAN | D13: HAFTA İÇİ 2 SAAT SALI | E13: 2 | F13: 150 | G13: 300
A14: 45704 | B14: ADMS | C14: SÜLEYMAN İP | D14: PAZAR MESAİ | E14: 10 | F14: 230 | G14: 2300
C15: EJDER COŞGUNOĞLU | D15: PAZAR MESAİ | E15: 10 | F15: 150 | G15: 1500
A16: 45731 | B16: (empty) | C16: SÜLEYMAN İP | D16: 2024- haftaiçi | E16: 18 | F16: 200 | G16: 3600
D17: 2024-Pazar | E17: 25 | F17: 200 | G17: 5000
A18: 45767 | B18: ADMS | C18: ŞENOL DURMUŞ | D18: PAZAR MESAİ | E18: 10 | F18: 250 | G18: 2500
C19: CUMA HAVAN | D19: PAZAR MESAİ | E19: 10 | F19: 150 | G19: 1500
A20: 45770 | B20: ADMS | C20: SÜLEYMAN İP | D20: 23NİSAN BAYRAM | E20: 10 | F20: 230 | G20: 2300
C21: EJDER COŞGUNOĞLU | D21: 23NİSAN BAYRAM | E21: 10 | F21: 150 | G21: 1500
A22: 45781 | B22: ADMS | C22: ŞENOL DURMUŞ | D22: PAZAR MESAİ | E22: 10 | F22: 250 | G22: 2500
C23: CUMA HAVAN | D23: PAZAR MESAİ | E23: 10 | F23: 150 | G23: 1500
A24: 45816 | B24: ADMS | C24: SÜLEYMAN İP | D24: BEKÇİLİK BAYRAM 3.GÜNÜ SABAH | E24: 5 | F24: 200 | G24: 1000
A25: 45817 | B25: ADMS | C25: SÜLEYMAN İP | D25: BEKÇİLİK BAYRAM 4.GÜNÜ SABAH | E25: 5 | F25: 200 | G25: 1000
A26: 45872 | B26: ADMS | C26: SÜLEYMAN İP | D26: PAZAR MESAİ | E26: 10 | F26: 230 | G26: 2300
C27: EJDER COŞGUNOĞLU | D27: PAZAR MESAİ | E27: 10 | F27: 150 | G27: 1500
A28: 45875 | B28: ADMS | C28: ŞENOL DURMUŞ | D28: ÇARŞAMBA 3 SAAT | E28: 3 | F28: 250 | G28: 750
C29: EJDER COŞGUNOĞLU | D29: ÇARŞAMBA 3 SAAT | E29: 3 | F29: 150 | G29: 450
A30: 45876 | B30: ADMS | C30: SÜLEYMAN İP | D30: PERŞEMBE 3 SAAT | E30: 3 | F30: 230 | G30: 690
C31: EJDER COŞGUNOĞLU | D31: PERŞEMBE 3 SAAT | E31: 3 | F31: 150 | G31: 450
A32: 45877 | B32: ADMS | C32: ŞENOL DURMUŞ | D32: CUMA MESAİ 3 SAAT | E32: 3 | F32: 250 | G32: 750
C33: EJDER COŞGUNOĞLU | D33: CUMA MESAİ 3 SAAT | E33: 3 | F33: 150 | G33: 450
A34: 45879 | B34: ADMS | C34: ŞENOL DURMUŞ | D34: PAZAR MESAİ | E34: 10 | F34: 250 | G34: 2500
C35: EJDER COŞGUNOĞLU | D35: PAZAR MESAİ | E35: 30 | F35: 150 | G35: 4500
A36: 45881 | B36: ADMS | C36: SÜLEYMAN İP | D36: SALI MESAİ 3 SAAT | E36: 3 | F36: 230 | G36: 690
C37: EJDER COŞGUNOĞLU | D37: SALI MESAİ 3 SAAT | E37: 3 | F37: 150 | G37: 450
A38: 45882 | B38: ADMS | C38: ŞENOL DURMUŞ | D38: ÇARŞAMBA 3 SAAT | E38: 3 | F38: 250 | G38: 750
A39: Total Result | G39: 48690

Sheet Mesai Takip
C1: T.Mesai: | D1: =SUBTOTAL(109,bordro810[M. Tutar]) -> #N/A | F1: T.Ödeme: | G1: =SUBTOTAL(109,bordro810[Ödeme]) -> 37240 | H1: Bakiye: | J1: =D1-G1 -> #N/A
A2: Tarih | B2: Personel | C2: İşlem | D2: Saat | E2: S.Ücret | F2: M. Tutar | G2: Ödeme | H2: Açıklama | I2: Bakiye | J2: Per. Bakiye | K2: YIL | L2: ay | M2: Gün | N2: grp | O2: Eski_M.Tutar | P2: Sütun1
A3: 45690 | B3: ÜMİT YİĞİT | C3: Mesai | D3: 10 | E3: =VLOOKUP(B3,PersonelListesi!A$1:G$41,5,FALSE()) -> 250 | F3: =bordro810[[#This Row],[Saat]]*bordro810[[#This Row],[S.Ücret]] -> 2500 | G3: 2500 | H3: PAZAR MESAİ | I3: =bordro810[[#This Row],[Ödeme]]-bordro810[[#This Row],[M. Tutar]] -> 0 | J3: =SUMIF(bordro810[Personel],bordro810[[#This Row],[Personel]],F$3:F3)-SUMIF(bordro810[Personel],bordro810[[#This Row],[Personel]],G$3:G3) -> 0 | K3: =TEXT(bordro810[[#This Row],[Tarih]],"yyyy") -> 2025 | L3: =TEXT(bordro810[[#This Row],[Tarih]],"yyyy/aa") -> 2025.aa | M3: =TEXT(bordro810[[#This Row],[Tarih]],"gggg") -> ADMS | N3: =VLOOKUP(B3,PersonelListesi!A$1:G$41,4,FALSE()) -> _OPERATÖR
A4: 45690 | B4: MUSTAFA KAHRAMAN | C4: Mesai | D4: 10 | E4: 230 | F4: =bordro810[[#This Row],[Saat]]*bordro810[[#This Row],[S.Ücret]] -> 2300 | G4: 2300 | H4: PAZAR MESAİ | I4: =bordro810[[#This Row],[Ödeme]]-bordro810[[#This Row],[M. Tutar]] -> 0 | J4: =SUMIF(bordro810[Personel],bordro810[[#This Row],[Personel]],F$3:F4)-SUMIF(bordro810[Personel],bordro810[[#This Row],[Personel]],G$3:G4) -> 5060 | K4: =TEXT(bordro810[[#This Row],[Tarih]],"yyyy") -> 2025 | L4: =TEXT(bordro810[[#This Row],[Tarih]],"yyyy/aa") -> 2025.aa | M4: =TEXT(bordro810[[#This Row],[Tarih]],"gggg") -> ADMS | N4: =VLOOKUP(B4,PersonelListesi!A$1:G$41,4,FALSE()) -> _ŞOFÖR
A5: 45690 | B5: OSMAN BİLGİN | C5: Mesai | D5: 10 | E5: 230 | F5: =bordro810[[#This Row],[Saat]]*bordro810[[#This Row],[S.Ücret]] -> 2300 | G5: 0 | H5: PAZAR MESAİ | I5: =bordro810[[#This Row],[Ödeme]]-bordro810[[#This Row],[M. Tutar]] -> -2300 | J5: =SUMIF(bordro810[Personel],bordro810[[#This Row],[Personel]],F$3:F5)-SUMIF(bordro810[Personel],bordro810[[#This Row],[Personel]],G$3:G5) -> 15030 | K5: =TEXT(bordro810[[#This Row],[Tarih]],"yyyy") -> 2025 | L5: =TEXT(bordro810[[#This Row],[Tarih]],"yyyy/aa") -> 2025.aa | M5: =TEXT(bordro810[[#This Row],[Tarih]],"gggg") -> ADMS | N5: =VLOOKUP(B5,PersonelListesi!A$1:G$41,4,FALSE()) -> _ŞOFÖR
A6: 45690 | B6: MEHMET ALİ ALTINOK | C6: Mesai | D6: 10 | E6: 250 | F6: =bordro810[[#This Row],[Saat]]*bordro810[[#This Row],[S.Ücret]] -> 2500 | G6: 0 | H6: PAZAR MESAİ | I6: =bordro810[[#This Row],[Ödeme]]-bordro810[[#This Row],[M. Tutar]] -> -2500 | J6: =SUMIF(bordro810[Personel],bordro810[[#This Row],[Personel]],F$3:F6)-SUMIF(bordro810[Personel],bordro810[[#This Row],[Personel]],G$3:G6) -> 5000 | K6: =TEXT(bordro810[[#This Row],[Tarih]],"yyyy") -> 2025 | L6: =TEXT(bordro810[[#This Row],[Tarih]],"yyyy/aa") -> 2025.aa | M6: =TEXT(bordro810[[#This Row],[Tarih]],"gggg") -> ADMS | N6: =VLOOKUP(B6,PersonelListesi!A$1:G$41,4,FALSE()) -> _OPERATÖR
A7: 45690 | B7: CİHAN DUYMAZ | C7: Mesai | D7: 10 | E7: 230 | F7: =bordro810[[#This Row],[Saat]]*bordro810[[#This Row],[S.Ücret]] -> 2300 | G7: 2300 | H7: PAZAR MESAİ | I7: =bordro810[[#This Row],[Ödeme]]-bordro810[[#This Row],[M. Tutar]] -> 0 | J7: =SUMIF(bordro810[Personel],bordro810[[#This Row],[Personel]],F$3:F7)-SUMIF(bordro810[Personel],bordro810[[#This Row],[Personel]],G$3:G7) -> 17240 | K7: =TEXT(bordro810[[#This Row],[Tarih]],"yyyy") -> 2025 | L7: =TEXT(bordro810[[#This Row],[Tarih]],"yyyy/aa") -> 2025.aa | M7: =TEXT(bordro810[[#This Row],[Tarih]],"gggg") -> ADMS | N7: =VLOOKUP(B7,PersonelListesi!A$1:G$41,4,FALSE()) -> _KANTAR
A8: 45690 | B8: ŞENOL DURMUŞ | C8: Mesai | D8: 10 | E8: 250 | F8: =bordro810[[#This Row],[Saat]]*bordro810[[#This Row],[S.Ücret]] -> 2500 | G8: 2500 | H8: PAZAR MESAİ | I8: =bordro810[[#This Row],[Ödeme]]-bordro810[[#This Row],[M. Tutar]] -> 0 | J8: =SUMIF(bordro810[Personel],bordro810[[#This Row],[Personel]],F$3:F8)-SUMIF(bordro810[Personel],bordro810[[#This Row],[Personel]],G$3:G8) -> 4750 | K8: =TEXT(bordro810[[#This Row],[Tarih]],"yyyy") -> 2025 | L8: =TEXT(bordro810[[#This Row],[Tarih]],"yyyy/aa") -> 2025.aa | M8: =TEXT(bordro810[[#This Row],[Tarih]],"gggg") -> ADMS | N8: =VLOOKUP(B8,PersonelListesi!A$1:G$41,4,FALSE()) -> _D.ELEMAN
A9: 45690 | B9: CUMA HAVAN | C9: Mesai | D9: 10 | E9: 150 | F9: =bordro810[[#This Row],[Saat]]*bordro810[[#This Row],[S.Ücret]] -> 1500 | G9: 0 | H9: PAZAR MESAİ | I9: =bordro810[[#This Row],[Ödeme]]-bordro810[[#This Row],[M. Tutar]] -> -1500 | J9: =SUMIF(bordro810[Personel],bordro810[[#This Row],[Personel]],F$3:F9)-SUMIF(bordro810[Personel],bordro810[[#This Row],[Personel]],G$3:G9) -> 5100 | K9: =TEXT(bordro810[[#This Row],[Tarih]],"yyyy") -> 2025 | L9: =TEXT(bordro810[[#This Row],[Tarih]],"yyyy/aa") -> 2025.aa | M9: =TEXT(bordro810[[#This Row],[Tarih]],"gggg") -> ADMS | N9: =VLOOKUP(B9,PersonelListesi!A$1:G$41,4,FALSE()) -> _D.ELEMAN
A10: 45692 | B10: HARUN ZEYBEK | C10: Mesai | D10: 2 | E10: 250 | F10: =bordro810[[#This Row],[Saat]]*bordro810[[#This Row],[S.Ücret]] -> 500 | G10: 500 | H10: HAFTA İÇİ 2 SAAT SALI | I10: =bordro810[[#This Row],[Ödeme]]-bordro810[[#This Row],[M. Tutar]] -> 0 | J10: =SUMIF(bordro810[Personel],bordro810[[#This Row],[Personel]],F$3:F10)-SUMIF(bordro810[Personel],bordro810[[#This Row],[Personel]],G$3:G10) -> 0 | K10: =TEXT(bordro810[[#This Row],[Tarih]],"yyyy") -> 2025 | L10: =TEXT(bordro810[[#This Row],[Tarih]],"yyyy/aa") -> 2025.aa | M10: =TEXT(bordro810[[#This Row],[Tarih]],"gggg") -> ADMS | N10: =VLOOKUP(B10,PersonelListesi!A$1:G$41,4,FALSE()) -> _OPERATÖR
A11: 45692 | B11: YILMAZ YILMAZ | C11: Mesai | D11: 2 | E11: 230 | F11: =bordro810[[#This Row],[Saat]]*bordro810[[#This Row],[S.Ücret]] -> 460 | G11: 460 | H11: HAFTA İÇİ 2 SAAT SALI | I11: =bordro810[[#This Row],[Ödeme]]-bordro810[[#This Row],[M. Tutar]] -> 0 | J11: =SUMIF(bordro810[Personel],bordro810[[#This Row],[Personel]],F$3:F11)-SUMIF(bordro810[Personel],bordro810[[#This Row],[Personel]],G$3:G11) -> 2300 | K11: =TEXT(bordro810[[#This Row],[Tarih]],"yyyy") -> 2025 | L11: =TEXT(bordro810[[#This Row],[Tarih]],"yyyy/aa") -> 2025.aa | M11: =TEXT(bordro810[[#This Row],[Tarih]],"gggg") -> ADMS | N11: =VLOOKUP(B11,PersonelListesi!A$1:G$41,4,FALSE()) -> _ŞOFÖR
A12: 45692 | B12: YAŞAR COŞKUN | C12: Mesai | D12: 2 | E12: 230 | F12: =bordro810[[#This Row],[Saat]]*bordro810[[#This Row],[S.Ücret]] -> 460 | G12: 0 | H12: HAFTA İÇİ 2 SAAT SALI | I12: =bordro810[[#This Row],[Ödeme]]-bordro810[[#This Row],[M. Tutar]] -> -460 | J12: =SUMIF(bordro810[Personel],bordro810[[#This Row],[Personel]],F$3:F12)-SUMIF(bordro810[Personel],bordro810[[#This Row],[Personel]],G$3:G12) -> 7820 | K12: =TEXT(bordro810[[#This Row],[Tarih]],"yyyy") -> 2025 | L12: =TEXT(bordro810[[#This Row],[Tarih]],"yyyy/aa") -> 2025.aa | M12: =TEXT(bordro810[[#This Row],[Tarih]],"gggg") -> ADMS | N12: =VLOOKUP(B12,PersonelListesi!A$1:G$41,4,FALSE()) -> _ŞOFÖR
A13: 45692 | B13: CUMA HAVAN | C13: Mesai | D13: 2 | E13: 150 | F13: =bordro810[[#This Row],[Saat]]*bordro810[[#This Row],[S.Ücret]] -> 300 | G13: 0 | H13: HAFTA İÇİ 2 SAAT SALI | I13: =bordro810[[#This Row],[Ödeme]]-bordro810[[#This Row],[M. Tutar]] -> -300 | J13: =SUMIF(bordro810[Personel],bordro810[[#This Row],[Personel]],F$3:F13)-SUMIF(bordro810[Personel],bordro810[[#This Row],[Personel]],G$3:G13) -> 5100 | K13: =TEXT(bordro810[[#This Row],[Tarih]],"yyyy") -> 2025 | L13: =TEXT(bordro810[[#This Row],[Tarih]],"yyyy/aa") -> 2025.aa | M13: =TEXT(bordro810[[#This Row],[Tarih]],"gggg") -> ADMS | N13: =VLOOKUP(B13,PersonelListesi!A$1:G$41,4,FALSE()) -> _D.ELEMAN
A14: 45692 | B14: SÜLEYMAN İP | C14: Mesai | D14: 2 | E14: 200 | F14: =bordro810[[#This Row],[Saat]]*bordro810[[#This Row],[S.Ücret]] -> 400 | G14: 0 | H14: HAFTA İÇİ 2 SAAT SALI | I14: =bordro810[[#This Row],[Ödeme]]-bordro810[[#This Row],[M. Tutar]] -> -400 | J14: =SUMIF(bordro810[Personel],bordro810[[#This Row],[Personel]],F$3:F14)-SUMIF(bordro810[Personel],bordro810[[#This Row],[Personel]],G$3:G14) -> 19740 | K14: =TEXT(bordro810[[#This Row],[Tarih]],"yyyy") -> 2025 | L14: =TEXT(bordro810[[#This Row],[Tarih]],"yyyy/aa") -> 2025.aa | M14: =TEXT(bordro810[[#This Row],[Tarih]],"gggg") -> ADMS | N14: =VLOOKUP(B14,PersonelListesi!A$1:G$41,4,FALSE()) -> _D.ELEMAN
A15: 45698 | B15: ÜMİT YİĞİT | C15: Mesai | D15: 2 | E15: 250 | F15: =bordro810[[#This Row],[Saat]]*bordro810[[#This Row],[S.Ücret]] -> 500 | G15: 500 | H15: HAFTA İÇİ 2 SAAT PAZARTESİ | I15: =bordro810[[#This Row],[Ödeme]]-bordro810[[#This Row],[M. Tutar]] -> 0 | J15: =SUMIF(bordro810[Personel],bordro810[[#This Row],[Personel]],F$3:F15)-SUMIF(bordro810[Personel],bordro810[[#This Row],[Personel]],G$3:G15) -> 0 | K15: =TEXT(bordro810[[#This Row],[Tarih]],"yyyy") -> 2025 | L15: =TEXT(bordro810[[#This Row],[Tarih]],"yyyy/aa") -> 2025.aa | M15: =TEXT(bordro810[[#This Row],[Tarih]],"gggg") -> ADMS | N15: =VLOOKUP(B15,PersonelListesi!A$1:G$41,4,FALSE()) -> _OPERATÖR
A16: 45698 | B16: MUSTAFA KAHRAMAN | C16: Mesai | D16: 2 | E16: 230 | F16: =bordro810[[#This Row],[Saat]]*bordro810[[#This Row],[S.Ücret]] -> 460 | G16: 460 | H16: HAFTA İÇİ 2 SAAT PAZARTESİ | I16: =bordro810[[#This Row],[Ödeme]]-bordro810[[#This Row],[M. Tutar]] -> 0 | J16: =SUMIF(bordro810[Personel],bordro810[[#This Row],[Personel]],F$3:F16)-SUMIF(bordro810[Personel],bordro810[[#This Row],[Personel]],G$3:G16) -> 5060 | K16: =TEXT(bordro810[[#This Row],[Tarih]],"yyyy") -> 2025 | L16: =TEXT(bordro810[[#This Row],[Tarih]],"yyyy/aa") -> 2025.aa | M16: =TEXT(bordro810[[#This Row],[Tarih]],"gggg") -> ADMS | N16: =VLOOKUP(B16,PersonelListesi!A$1:G$41,4,FALSE()) -> _ŞOFÖR
A17: 45698 | B17: OSMAN BİLGİN | C17: Mesai | D17: 2 | E17: 230 | F17: =bordro810[[#This Row],[Saat]]*bordro810[[#This Row],[S.Ücret]] -> 460 | G17: pp | H17: HAFTA İÇİ 2 SAAT PAZARTESİ | I17: =bordro810[[#This Row],[Ödeme]]-bordro810[[#This Row],[M. Tutar]] -> #VALUE! | J17: =SUMIF(bordro810[Personel],bordro810[[#This Row],[Personel]],F$3:F17)-SUMIF(bordro810[Personel],bordro810[[#This Row],[Personel]],G$3:G17) -> 15030 | K17: =TEXT(bordro810[[#This Row],[Tarih]],"yyyy") -> 2025 | L17: =TEXT(bordro810[[#This Row],[Tarih]],"yyyy/aa") -> 2025.aa | M17: =TEXT(bordro810[[#This Row],[Tarih]],"gggg") -> ADMS | N17: =VLOOKUP(B17,PersonelListesi!A$1:G$41,4,FALSE()) -> _ŞOFÖR
A18: 45698 | B18: SÜLEYMAN İP | C18: Mesai | D18: 2 | E18: 230 | F18: =bordro810[[#This Row],[Saat]]*bordro810[[#This Row],[S.Ücret]] -> 460 | G18: 0 | H18: HAFTA İÇİ 2 SAAT PAZARTESİ | I18: =bordro810[[#This Row],[Ödeme]]-bordro810[[#This Row],[M. Tutar]] -> -460 | J18: =SUMIF(bordro810[Personel],bordro810[[#This Row],[Personel]],F$3:F18)-SUMIF(bordro810[Personel],bordro810[[#This Row],[Personel]],G$3:G18) -> 19740 | K18: =TEXT(bordro810[[#This Row],[Tarih]],"yyyy") -> 2025 | L18: =TEXT(bordro810[[#This Row],[Tarih]],"yyyy/aa") -> 2025.aa | M18: =TEXT(bordro810[[#This Row],[Tarih]],"gggg") -> ADMS | N18: =VLOOKUP(B18,PersonelListesi!A$1:G$41,4,FALSE()) -> _D.ELEMAN
A19: 45698 | B19: EJDER COŞGUNOĞLU | C19: Mesai | D19: 2 | E19: 150 | F19: =bordro810[[#This Row],[Saat]]*bordro810[[#This Row],[S.Ücret]] -> 300 | G19: 300 | H19: HAFTA İÇİ 2 SAAT PAZARTESİ | I19: =bordro810[[#This Row],[Ödeme]]-bordro810[[#This Row],[M. Tutar]] -> 0 | J19: =SUMIF(bordro810[Personel],bordro810[[#This Row],[Personel]],F$3:F19)-SUMIF(bordro810[Personel],bordro810[[#This Row],[Personel]],G$3:G19) -> 9300 | K19: =TEXT(bordro810[[#This Row],[Tarih]],"yyyy") -> 2025 | L19: =TEXT(bordro810[[#This Row],[Tarih]],"yyyy/aa") -> 2025.aa | M19: =TEXT(bordro810[[#This Row],[Tarih]],"gggg") -> ADMS | N19: =VLOOKUP(B19,PersonelListesi!A$1:G$41,4,FALSE()) -> _D.ELEMAN
A20: 45699 | B20: HARUN ZEYBEK | C20: Mesai | D20: 2 | E20: 250 | F20: =bordro810[[#This Row],[Saat]]*bordro810[[#This Row],[S.Ücret]] -> 500 | G20: 500 | H20: HAFTA İÇİ 2 SAAT SALI | I20: =bordro810[[#This Row],[Ödeme]]-bordro810[[#This Row],[M. Tutar]] -> 0 | J20: =SUMIF(bordro810[Personel],bordro810[[#This Row],[Personel]],F$3:F20)-SUMIF(bordro810[Personel],bordro810[[#This Row],[Personel]],G$3:G20) -> 0 | K20: =TEXT(bordro810[[#This Row],[Tarih]],"yyyy") -> 2025 | L20: =TEXT(bordro810[[#This Row],[Tarih]],"yyyy/aa") -> 2025.aa | M20: =TEXT(bordro810[[#This Row],[Tarih]],"gggg") -> ADMS | N20: =VLOOKUP(B20,PersonelListesi!A$1:G$41,4,FALSE()) -> _OPERATÖR
A21: 45699 | B21: YILMAZ YILMAZ | C21: Mesai | D21: 2 | E21: 230 | F21: =bordro810[[#This Row],[Saat]]*bordro810[[#This Row],[S.Ücret]] -> 460 | G21: 460 | H21: HAFTA İÇİ 2 SAAT SALI | I21: =bordro810[[#This Row],[Ödeme]]-bordro810[[#This Row],[M. Tutar]] -> 0 | J21: =SUMIF(bordro810[Personel],bordro810[[#This Row],[Personel]],F$3:F21)-SUMIF(bordro810[Personel],bordro810[[#This Row],[Personel]],G$3:G21) -> 2300 | K21: =TEXT(bordro810[[#This Row],[Tarih]],"yyyy") -> 2025 | L21: =TEXT(bordro810[[#This Row],[Tarih]],"yyyy/aa") -> 2025.aa | M21: =TEXT(bordro810[[#This Row],[Tarih]],"gggg") -> ADMS | N21: =VLOOKUP(B21,PersonelListesi!A$1:G$41,4,FALSE()) -> _ŞOFÖR
A22: 45699 | B22: YAŞAR COŞKUN | C22: Mesai | D22: 2 | E22: 230 | F22: =bordro810[[#This Row],[Saat]]*bordro810[[#This Row],[S.Ücret]] -> 460 | G22: 460 | H22: HAFTA İÇİ 2 SAAT SALI | I22: =bordro810[[#This Row],[Ödeme]]-bordro810[[#This Row],[M. Tutar]] -> 0 | J22: =SUMIF(bordro810[Personel],bordro810[[#This Row],[Personel]],F$3:F22)-SUMIF(bordro810[Personel],bordro810[[#This Row],[Personel]],G$3:G22) -> 7820 | K22: =TEXT(bordro810[[#This Row],[Tarih]],"yyyy") -> 2025 | L22: =TEXT(bordro810[[#This Row],[Tarih]],"yyyy/aa") -> 2025.aa | M22: =TEXT(bordro810[[#This Row],[Tarih]],"gggg") -> ADMS | N22: =VLOOKUP(B22,PersonelListesi!A$1:G$41,4,FALSE()) -> _ŞOFÖR
A23: 45699 | B23: ŞENOL DURMUŞ | C23: Mesai | D23: 2 | E23: 250 | F23: =bordro810[[#This Row],[Saat]]*bordro810[[#This Row],[S.Ücret]] -> 500 | G23: 500 | H23: HAFTA İÇİ 2 SAAT SALI | I23: =bordro810[[#This Row],[Ödeme]]-bordro810[[#This Row],[M. Tutar]] -> 0 | J23: =SUMIF(bordro810[Personel],bordro810[[#This Row],[Personel]],F$3:F23)-SUMIF(bordro810[Personel],bordro810[[#This Row],[Personel]],G$3:G23) -> 4750 | K23: =TEXT(bordro810[[#This Row],[Tarih]],"yyyy") -> 2025 | L23: =TEXT(bordro810[[#This Row],[Tarih]],"yyyy/aa") -> 2025.aa | M23: =TEXT(bordro810[[#This Row],[Tarih]],"gggg") -> ADMS | N23: =VLOOKUP(B23,PersonelListesi!A$1:G$41,4,FALSE()) -> _D.ELEMAN
A24: 45699 | B24: CUMA HAVAN | C24: Mesai | D24: 2 | E24: 150 | F24: =bordro810[[#This Row],[Saat]]*bordro810[[#This Row],[S.Ücret]] -> 300 | G24: 0 | H24: HAFTA İÇİ 2 SAAT SALI | I24: =bordro810[[#This Row],[Ödeme]]-bordro810[[#This Row],[M. Tutar]] -> -300 | J24: =SUMIF(bordro810[Personel],bordro810[[#This Row],[Personel]],F$3:F24)-SUMIF(bordro810[Personel],bordro810[[#This Row],[Personel]],G$3:G24) -> 5100 | K24: =TEXT(bordro810[[#This Row],[Tarih]],"yyyy") -> 2025 | L24: =TEXT(bordro810[[#This Row],[Tarih]],"yyyy/aa") -> 2025.aa | M24: =TEXT(bordro810[[#This Row],[Tarih]],"gggg") -> ADMS | N24: =VLOOKUP(B24,PersonelListesi!A$1:G$41,4,FALSE()) -> _D.ELEMAN
A25: 45704 | B25: ÜMİT YİĞİT | C25: Mesai | D25: 10 | E25: 250 | F25: =bordro810[[#This Row],[Saat]]*bordro810[[#This Row],[S.Ücret]] -> 2500 | G25: 2500 | H25: PAZAR MESAİ | I25: =bordro810[[#This Row],[Ödeme]]-bordro810[[#This Row],[M. Tutar]] -> 0 | J25: =SUMIF(bordro810[Personel],bordro810[[#This Row],[Personel]],F$3:F25)-SUMIF(bordro810[Personel],bordro810[[#This Row],[Personel]],G$3:G25) -> 0 | K25: =TEXT(bordro810[[#This Row],[Tarih]],"yyyy") -> 2025 | L25: =TEXT(bordro810[[#This Row],[Tarih]],"yyyy/aa") -> 2025.aa | M25: =TEXT(bordro810[[#This Row],[Tarih]],"gggg") -> ADMS | N25: =VLOOKUP(B25,PersonelListesi!A$1:G$41,4,FALSE()) -> _OPERATÖR
A26: 45704 | B26: MUSTAFA KAHRAMAN | C26: Mesai | D26: 10 | E26: 230 | F26: =bordro810[[#This Row],[Saat]]*bordro810[[#This Row],[S.Ücret]] -> 2300 | G26: 2300 | H26: PAZAR MESAİ | I26: =bordro810[[#This Row],[Ödeme]]-bordro810[[#This Row],[M. Tutar]] -> 0 | J26: =SUMIF(bordro810[Personel],bordro810[[#This Row],[Personel]],F$3:F26)-SUMIF(bordro810[Personel],bordro810[[#This Row],[Personel]],G$3:G26) -> 5060 | K26: =TEXT(bordro810[[#This Row],[Tarih]],"yyyy") -> 2025 | L26: =TEXT(bordro810[[#This Row],[Tarih]],"yyyy/aa") -> 2025.aa | M26: =TEXT(bordro810[[#This Row],[Tarih]],"gggg") -> ADMS | N26: =VLOOKUP(B26,PersonelListesi!A$1:G$41,4,FALSE()) -> _ŞOFÖR
